Workbook

Sheet Шкалы
A1: Дилер | B1: Тип | C1: Раздел | D1: Категория | E1: Таблица | F1: Показатель | G1: № строки | H1: Итог | I1: Тир | J1: № тира | K1: Тир от | L1: Тир до | M1: Значение | N1: Единица | O1: Вкладка (была) | P1: Ячейка в исходнике | Q1: Ключ: строка | R1: Ключ: тир | S1: Ключ: значение | T1: Ключ: порядок строки | U1: Ключ: итог | V1: Ключ: колонка плана
A2: КОМПО Технолоджис | B2: РФ | C2: План | D2: Итого по дилеру | E2: План и бонусы | F2: Выручка 2024 | G2: 1 | J2: 1 | M2: 4164812 | N2: EUR | O2: КТ | P2: D4 | Q2: =A2&"|"&C2&"|"&D2&"|"&G2 -> КОМПО Технолоджис|План|Итого по дилеру|1 | R2: =A2&"|"&C2&"|"&D2&"|"&J2 -> КОМПО Технолоджис|План|Итого по дилеру|1 | S2: =A2&"|"&C2&"|"&D2&"|"&G2&"|"&J2 -> КОМПО Технолоджис|План|Итого по дилеру|1|1 | T2: =A2&"|"&C2&"|"&G2 -> КОМПО Технолоджис|План|1 | U2: =IF(H2="да",A2&"|"&C2&"|"&D2&"|"&J2,"") | V2: =IF(C2="План",A2&"|"&J2,"") -> КОМПО Технолоджис|1
A3: КОМПО Технолоджис | B3: РФ | C3: План | D3: Итого по дилеру | E3: План и бонусы | F3: Выручка 2025 | G3: 1 | J3: 2 | M3: 4121760 | N3: EUR | O3: КТ | P3: E4 | Q3: =A3&"|"&C3&"|"&D3&"|"&G3 -> КОМПО Технолоджис|План|Итого по дилеру|1 | R3: =A3&"|"&C3&"|"&D3&"|"&J3 -> КОМПО Технолоджис|План|Итого по дилеру|2 | S3: =A3&"|"&C3&"|"&D3&"|"&G3&"|"&J3 -> КОМПО Технолоджис|План|Итого по дилеру|1|2 | T3: =A3&"|"&C3&"|"&G3 -> КОМПО Технолоджис|План|1 | U3: =IF(H3="да",A3&"|"&C3&"|"&D3&"|"&J3,"") | V3: =IF(C3="План",A3&"|"&J3,"") -> КОМПО Технолоджис|2
A4: КОМПО Технолоджис | B4: РФ | C4: План | D4: Итого по дилеру | E4: План и бонусы | F4: План 2026 | G4: 1 | J4: 3 | M4: 4142912 | N4: EUR | O4: КТ | P4: F4 | Q4: =A4&"|"&C4&"|"&D4&"|"&G4 -> КОМПО Технолоджис|План|Итого по дилеру|1 | R4: =A4&"|"&C4&"|"&D4&"|"&J4 -> КОМПО Технолоджис|План|Итого по дилеру|3 | S4: =A4&"|"&C4&"|"&D4&"|"&G4&"|"&J4 -> КОМПО Технолоджис|План|Итого по дилеру|1|3 | T4: =A4&"|"&C4&"|"&G4 -> КОМПО Технолоджис|План|1 | U4: =IF(H4="да",A4&"|"&C4&"|"&D4&"|"&J4,"") | V4: =IF(C4="План",A4&"|"&J4,"") -> КОМПО Технолоджис|3
A5: КОМПО Технолоджис | B5: РФ | C5: План | D5: Итого по дилеру | E5: План и бонусы | F5: Прирост П/Ф | G5: 1 | J5: 4 | M5: 0.0051317859 | N5: % | O5: КТ | P5: G4 | Q5: =A5&"|"&C5&"|"&D5&"|"&G5 -> КОМПО Технолоджис|План|Итого по дилеру|1 | R5: =A5&"|"&C5&"|"&D5&"|"&J5 -> КОМПО Технолоджис|План|Итого по дилеру|4 | S5: =A5&"|"&C5&"|"&D5&"|"&G5&"|"&J5 -> КОМПО Технолоджис|План|Итого по дилеру|1|4 | T5: =A5&"|"&C5&"|"&G5 -> КОМПО Технолоджис|План|1 | U5: =IF(H5="да",A5&"|"&C5&"|"&D5&"|"&J5,"") | V5: =IF(C5="План",A5&"|"&J5,"") -> КОМПО Технолоджис|4
A6: КОМПО Технолоджис | B6: РФ | C6: План | D6: Сервис | E6: План и бонусы | F6: Выручка 2024 | G6: 2 | J6: 1 | M6: 346883 | N6: EUR | O6: КТ | P6: D5 | Q6: =A6&"|"&C6&"|"&D6&"|"&G6 -> КОМПО Технолоджис|План|Сервис|2 | R6: =A6&"|"&C6&"|"&D6&"|"&J6 -> КОМПО Технолоджис|План|Сервис|1 | S6: =A6&"|"&C6&"|"&D6&"|"&G6&"|"&J6 -> КОМПО Технолоджис|План|Сервис|2|1 | T6: =A6&"|"&C6&"|"&G6 -> КОМПО Технолоджис|План|2 | U6: =IF(H6="да",A6&"|"&C6&"|"&D6&"|"&J6,"") | V6: =IF(C6="План",A6&"|"&J6,"") -> КОМПО Технолоджис|1
A7: КОМПО Технолоджис | B7: РФ | C7: План | D7: Сервис | E7: План и бонусы | F7: Выручка 2025 | G7: 2 | J7: 2 | M7: 448343 | N7: EUR | O7: КТ | P7: E5 | Q7: =A7&"|"&C7&"|"&D7&"|"&G7 -> КОМПО Технолоджис|План|Сервис|2 | R7: =A7&"|"&C7&"|"&D7&"|"&J7 -> КОМПО Технолоджис|План|Сервис|2 | S7: =A7&"|"&C7&"|"&D7&"|"&G7&"|"&J7 -> КОМПО Технолоджис|План|Сервис|2|2 | T7: =A7&"|"&C7&"|"&G7 -> КОМПО Технолоджис|План|2 | U7: =IF(H7="да",A7&"|"&C7&"|"&D7&"|"&J7,"") | V7: =IF(C7="План",A7&"|"&J7,"") -> КОМПО Технолоджис|2
A8: КОМПО Технолоджис | B8: РФ | C8: План | D8: Сервис | E8: План и бонусы | F8: План 2026 | G8: 2 | J8: 3 | M8: 480438 | N8: EUR | O8: КТ | P8: F5 | Q8: =A8&"|"&C8&"|"&D8&"|"&G8 -> КОМПО Технолоджис|План|Сервис|2 | R8: =A8&"|"&C8&"|"&D8&"|"&J8 -> КОМПО Технолоджис|План|Сервис|3 | S8: =A8&"|"&C8&"|"&D8&"|"&G8&"|"&J8 -> КОМПО Технолоджис|План|Сервис|2|3 | T8: =A8&"|"&C8&"|"&G8 -> КОМПО Технолоджис|План|2 | U8: =IF(H8="да",A8&"|"&C8&"|"&D8&"|"&J8,"") | V8: =IF(C8="План",A8&"|"&J8,"") -> КОМПО Технолоджис|3
A9: КОМПО Технолоджис | B9: РФ | C9: План | D9: Сервис | E9: План и бонусы | F9: Размер бонуса по итогам 2026 г | G9: 2 | J9: 5 | M9: 0.01 | N9: % | O9: КТ | P9: H5 | Q9: =A9&"|"&C9&"|"&D9&"|"&G9 -> КОМПО Технолоджис|План|Сервис|2 | R9: =A9&"|"&C9&"|"&D9&"|"&J9 -> КОМПО Технолоджис|План|Сервис|5 | S9: =A9&"|"&C9&"|"&D9&"|"&G9&"|"&J9 -> КОМПО Технолоджис|План|Сервис|2|5 | T9: =A9&"|"&C9&"|"&G9 -> КОМПО Технолоджис|План|2 | U9: =IF(H9="да",A9&"|"&C9&"|"&D9&"|"&J9,"") | V9: =IF(C9="План",A9&"|"&J9,"") -> КОМПО Технолоджис|5
A10: КОМПО Технолоджис | B10: РФ | C10: План | D10: Сервис | E10: План и бонусы | F10: Скидка в 1 кв. 2026 ф.г.* | G10: 2 | J10: 6 | M10: 0.3 | N10: % | O10: КТ | P10: I5 | Q10: =A10&"|"&C10&"|"&D10&"|"&G10 -> КОМПО Технолоджис|План|Сервис|2 | R10: =A10&"|"&C10&"|"&D10&"|"&J10 -> КОМПО Технолоджис|План|Сервис|6 | S10: =A10&"|"&C10&"|"&D10&"|"&G10&"|"&J10 -> КОМПО Технолоджис|План|Сервис|2|6 | T10: =A10&"|"&C10&"|"&G10 -> КОМПО Технолоджис|План|2 | U10: =IF(H10="да",A10&"|"&C10&"|"&D10&"|"&J10,"") | V10: =IF(C10="План",A10&"|"&J10,"") -> КОМПО Технолоджис|6
A11: КОМПО Технолоджис | B11: РФ | C11: План | D11: Оборудование | E11: План и бонусы | F11: Выручка 2024 | G11: 3 | J11: 1 | M11: 2205660 | N11: EUR | O11: КТ | P11: D6 | Q11: =A11&"|"&C11&"|"&D11&"|"&G11 -> КОМПО Технолоджис|План|Оборудование|3 | R11: =A11&"|"&C11&"|"&D11&"|"&J11 -> КОМПО Технолоджис|План|Оборудование|1 | S11: =A11&"|"&C11&"|"&D11&"|"&G11&"|"&J11 -> КОМПО Технолоджис|План|Оборудование|3|1 | T11: =A11&"|"&C11&"|"&G11 -> КОМПО Технолоджис|План|3 | U11: =IF(H11="да",A11&"|"&C11&"|"&D11&"|"&J11,"") | V11: =IF(C11="План",A11&"|"&J11,"") -> КОМПО Технолоджис|1
A12: КОМПО Технолоджис | B12: РФ | C12: План | D12: Оборудование | E12: План и бонусы | F12: Выручка 2025 | G12: 3 | J12: 2 | M12: 1710368 | N12: EUR | O12: КТ | P12: E6 | Q12: =A12&"|"&C12&"|"&D12&"|"&G12 -> КОМПО Технолоджис|План|Оборудование|3 | R12: =A12&"|"&C12&"|"&D12&"|"&J12 -> КОМПО Технолоджис|План|Оборудование|2 | S12: =A12&"|"&C12&"|"&D12&"|"&G12&"|"&J12 -> КОМПО Технолоджис|План|Оборудование|3|2 | T12: =A12&"|"&C12&"|"&G12 -> КОМПО Технолоджис|План|3 | U12: =IF(H12="да",A12&"|"&C12&"|"&D12&"|"&J12,"") | V12: =IF(C12="План",A12&"|"&J12,"") -> КОМПО Технолоджис|2
A13: КОМПО Технолоджис | B13: РФ | C13: План | D13: Оборудование | E13: План и бонусы | F13: План 2026 | G13: 3 | J13: 3 | M13: 2020593.8 | N13: EUR | O13: КТ | P13: F6 | Q13: =A13&"|"&C13&"|"&D13&"|"&G13 -> КОМПО Технолоджис|План|Оборудование|3 | R13: =A13&"|"&C13&"|"&D13&"|"&J13 -> КОМПО Технолоджис|План|Оборудование|3 | S13: =A13&"|"&C13&"|"&D13&"|"&G13&"|"&J13 -> КОМПО Технолоджис|План|Оборудование|3|3 | T13: =A13&"|"&C13&"|"&G13 -> КОМПО Технолоджис|План|3 | U13: =IF(H13="да",A13&"|"&C13&"|"&D13&"|"&J13,"") | V13: =IF(C13="План",A13&"|"&J13,"") -> КОМПО Технолоджис|3
... A20: КОМПО Технолоджис | B20: РФ | C20: План | D20: Расходные материалы | E20: План и бонусы | F20: Скидка в 1 кв. 2026 ф.г.* | G20: 4 | J20: 6 | M20: 0.06 | N20: % | O20: КТ | P20: I7 | Q20: =A20&"|"&C20&"|"&D20&"|"&G20 -> КОМПО Технолоджис|План|Расходные материалы|4 | R20: =A20&"|"&C20&"|"&D20&"|"&J20 -> КОМПО Технолоджис|План|Расходные материалы|6 | S20: =A20&"|"&C20&"|"&D20&"|"&G20&"|"&J20 -> КОМПО Технолоджис|План|Расходные материалы|4|6 | T20: =A20&"|"&C20&"|"&G20 -> КОМПО Технолоджис|План|4 | U20: =IF(H20="да",A20&"|"&C20&"|"&D20&"|"&J20,"") | V20: =IF(C20="План",A20&"|"&J20,"") -> КОМПО Технолоджис|6
A21: КОМПО Технолоджис | B21: РФ | C21: Шкала | D21: Оборудование | E21: Оборудование — за квартал | F21: 1 Базовое вознаграждение за Дилерский договор | G21: 1 | I21: до 75 | J21: 1 | M21: 0.06 | N21: % | O21: КТ | P21: E13 | Q21: =A21&"|"&C21&"|"&D21&"|"&G21 -> КОМПО Технолоджис|Шкала|Оборудование|1 | R21: =A21&"|"&C21&"|"&D21&"|"&J21 -> КОМПО Технолоджис|Шкала|Оборудование|1 | S21: =A21&"|"&C21&"|"&D21&"|"&G21&"|"&J21 -> КОМПО Технолоджис|Шкала|Оборудование|1|1 | T21: =A21&"|"&C21&"|"&G21 -> КОМПО Технолоджис|Шкала|1 | U21: =IF(H21="да",A21&"|"&C21&"|"&D21&"|"&J21,"") | V21: =IF(C21="План",A21&"|"&J21,"")
A22: КОМПО Технолоджис | B22: РФ | C22: Шкала | D22: Оборудование | E22: Оборудование — за квартал | F22: 1 Базовое вознаграждение за Дилерский договор | G22: 1 | I22: 75-114 | J22: 2 | M22: 0.06 | N22: % | O22: КТ | P22: F13 | Q22: =A22&"|"&C22&"|"&D22&"|"&G22 -> КОМПО Технолоджис|Шкала|Оборудование|1 | R22: =A22&"|"&C22&"|"&D22&"|"&J22 -> КОМПО Технолоджис|Шкала|Оборудование|2 | S22: =A22&"|"&C22&"|"&D22&"|"&G22&"|"&J22 -> КОМПО Технолоджис|Шкала|Оборудование|1|2 | T22: =A22&"|"&C22&"|"&G22 -> КОМПО Технолоджис|Шкала|1 | U22: =IF(H22="да",A22&"|"&C22&"|"&D22&"|"&J22,"") | V22: =IF(C22="План",A22&"|"&J22,"")
A23: КОМПО Технолоджис | B23: РФ | C23: Шкала | D23: Оборудование | E23: Оборудование — за квартал | F23: 1 Базовое вознаграждение за Дилерский договор | G23: 1 | I23: 115-149 | J23: 3 | M23: 0.06 | N23: % | O23: КТ | P23: G13 | Q23: =A23&"|"&C23&"|"&D23&"|"&G23 -> КОМПО Технолоджис|Шкала|Оборудование|1 | R23: =A23&"|"&C23&"|"&D23&"|"&J23 -> КОМПО Технолоджис|Шкала|Оборудование|3 | S23: =A23&"|"&C23&"|"&D23&"|"&G23&"|"&J23 -> КОМПО Технолоджис|Шкала|Оборудование|1|3 | T23: =A23&"|"&C23&"|"&G23 -> КОМПО Технолоджис|Шкала|1 | U23: =IF(H23="да",A23&"|"&C23&"|"&D23&"|"&J23,"") | V23: =IF(C23="План",A23&"|"&J23,"")
A24: КОМПО Технолоджис | B24: РФ | C24: Шкала | D24: Оборудование | E24: Оборудование — за квартал | F24: 1 Базовое вознаграждение за Дилерский договор | G24: 1 | I24: 150-189 | J24: 4 | M24: 0.06 | N24: % | O24: КТ | P24: H13 | Q24: =A24&"|"&C24&"|"&D24&"|"&G24 -> КОМПО Технолоджис|Шкала|Оборудование|1 | R24: =A24&"|"&C24&"|"&D24&"|"&J24 -> КОМПО Технолоджис|Шкала|Оборудование|4 | S24: =A24&"|"&C24&"|"&D24&"|"&G24&"|"&J24 -> КОМПО Технолоджис|Шкала|Оборудование|1|4 | T24: =A24&"|"&C24&"|"&G24 -> КОМПО Технолоджис|Шкала|1 | U24: =IF(H24="да",A24&"|"&C24&"|"&D24&"|"&J24,"") | V24: =IF(C24="План",A24&"|"&J24,"")
A25: КОМПО Технолоджис | B25: РФ | C25: Шкала | D25: Оборудование | E25: Оборудование — за квартал | F25: 1 Базовое вознаграждение за Дилерский договор | G25: 1 | I25: 190-224 | J25: 5 | M25: 0.06 | N25: % | O25: КТ | P25: I13 | Q25: =A25&"|"&C25&"|"&D25&"|"&G25 -> КОМПО Технолоджис|Шкала|Оборудование|1 | R25: =A25&"|"&C25&"|"&D25&"|"&J25 -> КОМПО Технолоджис|Шкала|Оборудование|5 | S25: =A25&"|"&C25&"|"&D25&"|"&G25&"|"&J25 -> КОМПО Технолоджис|Шкала|Оборудование|1|5 | T25: =A25&"|"&C25&"|"&G25 -> КОМПО Технолоджис|Шкала|1 | U25: =IF(H25="да",A25&"|"&C25&"|"&D25&"|"&J25,"") | V25: =IF(C25="План",A25&"|"&J25,"")
A26: КОМПО Технолоджис | B26: РФ | C26: Шкала | D26: Оборудование | E26: Оборудование — за квартал | F26: 1 Базовое вознаграждение за Дилерский договор | G26: 1 | I26: 225 и более | J26: 6 | M26: 0.06 | N26: % | O26: КТ | P26: J13 | Q26: =A26&"|"&C26&"|"&D26&"|"&G26 -> КОМПО Технолоджис|Шкала|Оборудование|1 | R26: =A26&"|"&C26&"|"&D26&"|"&J26 -> КОМПО Технолоджис|Шкала|Оборудование|6 | S26: =A26&"|"&C26&"|"&D26&"|"&G26&"|"&J26 -> КОМПО Технолоджис|Шкала|Оборудование|1|6 | T26: =A26&"|"&C26&"|"&G26 -> КОМПО Технолоджис|Шкала|1 | U26: =IF(H26="да",A26&"|"&C26&"|"&D26&"|"&J26,"") | V26: =IF(C26="План",A26&"|"&J26,"")
A27: КОМПО Технолоджис | B27: РФ | C27: Шкала | D27: Оборудование | E27: Оборудование — за квартал | F27: 2.1.1. Сервисный центр | G27: 2 | I27: до 75 | J27: 1 | M27: 0.06 | N27: % | O27: КТ | P27: E14 | Q27: =A27&"|"&C27&"|"&D27&"|"&G27 -> КОМПО Технолоджис|Шкала|Оборудование|2 | R27: =A27&"|"&C27&"|"&D27&"|"&J27 -> КОМПО Технолоджис|Шкала|Оборудование|1 | S27: =A27&"|"&C27&"|"&D27&"|"&G27&"|"&J27 -> КОМПО Технолоджис|Шкала|Оборудование|2|1 | T27: =A27&"|"&C27&"|"&G27 -> КОМПО Технолоджис|Шкала|2 | U27: =IF(H27="да",A27&"|"&C27&"|"&D27&"|"&J27,"") | V27: =IF(C27="План",A27&"|"&J27,"")
A28: КОМПО Технолоджис | B28: РФ | C28: Шкала | D28: Оборудование | E28: Оборудование — за квартал | F28: 2.1.1. Сервисный центр | G28: 2 | I28: 75-114 | J28: 2 | M28: 0.06 | N28: % | O28: КТ | P28: F14 | Q28: =A28&"|"&C28&"|"&D28&"|"&G28 -> КОМПО Технолоджис|Шкала|Оборудование|2 | R28: =A28&"|"&C28&"|"&D28&"|"&J28 -> КОМПО Технолоджис|Шкала|Оборудование|2 | S28: =A28&"|"&C28&"|"&D28&"|"&G28&"|"&J28 -> КОМПО Технолоджис|Шкала|Оборудование|2|2 | T28: =A28&"|"&C28&"|"&G28 -> КОМПО Технолоджис|Шкала|2 | U28: =IF(H28="да",A28&"|"&C28&"|"&D28&"|"&J28,"") | V28: =IF(C28="План",A28&"|"&J28,"")
A29: КОМПО Технолоджис | B29: РФ | C29: Шкала | D29: Оборудование | E29: Оборудование — за квартал | F29: 2.1.1. Сервисный центр | G29: 2 | I29: 115-149 | J29: 3 | M29: 0.06 | N29: % | O29: КТ | P29: G14 | Q29: =A29&"|"&C29&"|"&D29&"|"&G29 -> КОМПО Технолоджис|Шкала|Оборудование|2 | R29: =A29&"|"&C29&"|"&D29&"|"&J29 -> КОМПО Технолоджис|Шкала|Оборудование|3 | S29: =A29&"|"&C29&"|"&D29&"|"&G29&"|"&J29 -> КОМПО Технолоджис|Шкала|Оборудование|2|3 | T29: =A29&"|"&C29&"|"&G29 -> КОМПО Технолоджис|Шкала|2 | U29: =IF(H29="да",A29&"|"&C29&"|"&D29&"|"&J29,"") | V29: =IF(C29="План",A29&"|"&J29,"")
A30: КОМПО Технолоджис | B30: РФ | C30: Шкала | D30: Оборудование | E30: Оборудование — за квартал | F30: 2.1.1. Сервисный центр | G30: 2 | I30: 150-189 | J30: 4 | M30: 0.06 | N30: % | O30: КТ | P30: H14 | Q30: =A30&"|"&C30&"|"&D30&"|"&G30 -> КОМПО Технолоджис|Шкала|Оборудование|2 | R30: =A30&"|"&C30&"|"&D30&"|"&J30 -> КОМПО Технолоджис|Шкала|Оборудование|4 | S30: =A30&"|"&C30&"|"&D30&"|"&G30&"|"&J30 -> КОМПО Технолоджис|Шкала|Оборудование|2|4 | T30: =A30&"|"&C30&"|"&G30 -> КОМПО Технолоджис|Шкала|2 | U30: =IF(H30="да",A30&"|"&C30&"|"&D30&"|"&J30,"") | V30: =IF(C30="План",A30&"|"&J30,"")
A31: КОМПО Технолоджис | B31: РФ | C31: Шкала | D31: Оборудование | E31: Оборудование — за квартал | F31: 2.1.1. Сервисный центр | G31: 2 | I31: 190-224 | J31: 5 | M31: 0.06 | N31: % | O31: КТ | P31: I14 | Q31: =A31&"|"&C31&"|"&D31&"|"&G31 -> КОМПО Технолоджис|Шкала|Оборудование|2 | R31: =A31&"|"&C31&"|"&D31&"|"&J31 -> КОМПО Технолоджис|Шкала|Оборудование|5 | S31: =A31&"|"&C31&"|"&D31&"|"&G31&"|"&J31 -> КОМПО Технолоджис|Шкала|Оборудование|2|5 | T31: =A31&"|"&C31&"|"&G31 -> КОМПО Технолоджис|Шкала|2 | U31: =IF(H31="да",A31&"|"&C31&"|"&D31&"|"&J31,"") | V31: =IF(C31="План",A31&"|"&J31,"")
A32: КОМПО Технолоджис | B32: РФ | C32: Шкала | D32: Оборудование | E32: Оборудование — за квартал | F32: 2.1.1. Сервисный центр | G32: 2 | I32: 225 и более | J32: 6 | M32: 0.06 | N32: % | O32: КТ | P32: J14 | Q32: =A32&"|"&C32&"|"&D32&"|"&G32 -> КОМПО Технолоджис|Шкала|Оборудование|2 | R32: =A32&"|"&C32&"|"&D32&"|"&J32 -> КОМПО Технолоджис|Шкала|Оборудование|6 | S32: =A32&"|"&C32&"|"&D32&"|"&G32&"|"&J32 -> КОМПО Технолоджис|Шкала|Оборудование|2|6 | T32: =A32&"|"&C32&"|"&G32 -> КОМПО Технолоджис|Шкала|2 | U32: =IF(H32="да",A32&"|"&C32&"|"&D32&"|"&J32,"") | V32: =IF(C32="План",A32&"|"&J32,"")
... A50: КОМПО Технолоджис | B50: РФ | C50: Шкала | D50: Оборудование | E50: Оборудование — за квартал | F50: 3 Объем закупок МП | G50: 5 | I50: 225 и более | J50: 6 | M50: 0.05 | N50: % | O50: КТ | P50: J17 | Q50: =A50&"|"&C50&"|"&D50&"|"&G50 -> КОМПО Технолоджис|Шкала|Оборудование|5 | R50: =A50&"|"&C50&"|"&D50&"|"&J50 -> КОМПО Технолоджис|Шкала|Оборудование|6 | S50: =A50&"|"&C50&"|"&D50&"|"&G50&"|"&J50 -> КОМПО Технолоджис|Шкала|Оборудование|5|6 | T50: =A50&"|"&C50&"|"&G50 -> КОМПО Технолоджис|Шкала|5 | U50: =IF(H50="да",A50&"|"&C50&"|"&D50&"|"&J50,"") | V50: =IF(C50="План",A50&"|"&J50,"")
A51: КОМПО Технолоджис | B51: РФ | C51: Шкала | D51: Оборудование | E51: Оборудование — за квартал | F51: ИТОГО по МП: | G51: 6 | H51: да | I51: до 75 | J51: 1 | M51: 0.14 | N51: % | O51: КТ | P51: E18 | Q51: =A51&"|"&C51&"|"&D51&"|"&G51 -> КОМПО Технолоджис|Шкала|Оборудование|6 | R51: =A51&"|"&C51&"|"&D51&"|"&J51 -> КОМПО Технолоджис|Шкала|Оборудование|1 | S51: =A51&"|"&C51&"|"&D51&"|"&G51&"|"&J51 -> КОМПО Технолоджис|Шкала|Оборудование|6|1 | T51: =A51&"|"&C51&"|"&G51 -> КОМПО Технолоджис|Шкала|6 | U51: =IF(H51="да",A51&"|"&C51&"|"&D51&"|"&J51,"") -> КОМПО Технолоджис|Шкала|Оборудование|1 | V51: =IF(C51="План",A51&"|"&J51,"")
A52: КОМПО Технолоджис | B52: РФ | C52: Шкала | D52: Оборудование | E52: Оборудование — за квартал | F52: ИТОГО по МП: | G52: 6 | H52: да | I52: 75-114 | J52: 2 | M52: 0.15 | N52: % | O52: КТ | P52: F18 | Q52: =A52&"|"&C52&"|"&D52&"|"&G52 -> КОМПО Технолоджис|Шкала|Оборудование|6 | R52: =A52&"|"&C52&"|"&D52&"|"&J52 -> КОМПО Технолоджис|Шкала|Оборудование|2 | S52: =A52&"|"&C52&"|"&D52&"|"&G52&"|"&J52 -> КОМПО Технолоджис|Шкала|Оборудование|6|2 | T52: =A52&"|"&C52&"|"&G52 -> КОМПО Технолоджис|Шкала|6 | U52: =IF(H52="да",A52&"|"&C52&"|"&D52&"|"&J52,"") -> КОМПО Технолоджис|Шкала|Оборудование|2 | V52: =IF(C52="План",A52&"|"&J52,"")
A53: КОМПО Технолоджис | B53: РФ | C53: Шкала | D53: Оборудование | E53: Оборудование — за квартал | F53: ИТОГО по МП: | G53: 6 | H53: да | I53: 115-149 | J53: 3 | M53: 0.16 | N53: % | O53: КТ | P53: G18 | Q53: =A53&"|"&C53&"|"&D53&"|"&G53 -> КОМПО Технолоджис|Шкала|Оборудование|6 | R53: =A53&"|"&C53&"|"&D53&"|"&J53 -> КОМПО Технолоджис|Шкала|Оборудование|3 | S53: =A53&"|"&C53&"|"&D53&"|"&G53&"|"&J53 -> КОМПО Технолоджис|Шкала|Оборудование|6|3 | T53: =A53&"|"&C53&"|"&G53 -> КОМПО Технолоджис|Шкала|6 | U53: =IF(H53="да",A53&"|"&C53&"|"&D53&"|"&J53,"") -> КОМПО Технолоджис|Шкала|Оборудование|3 | V53: =IF(C53="План",A53&"|"&J53,"")
A54: КОМПО Технолоджис | B54: РФ | C54: Шкала | D54: Оборудование | E54: Оборудование — за квартал | F54: ИТОГО по МП: | G54: 6 | H54: да | I54: 150-189 | J54: 4 | M54: 0.17 | N54: % | O54: КТ | P54: H18 | Q54: =A54&"|"&C54&"|"&D54&"|"&G54 -> КОМПО Технолоджис|Шкала|Оборудование|6 | R54: =A54&"|"&C54&"|"&D54&"|"&J54 -> КОМПО Технолоджис|Шкала|Оборудование|4 | S54: =A54&"|"&C54&"|"&D54&"|"&G54&"|"&J54 -> КОМПО Технолоджис|Шкала|Оборудование|6|4 | T54: =A54&"|"&C54&"|"&G54 -> КОМПО Технолоджис|Шкала|6 | U54: =IF(H54="да",A54&"|"&C54&"|"&D54&"|"&J54,"") -> КОМПО Технолоджис|Шкала|Оборудование|4 | V54: =IF(C54="План",A54&"|"&J54,"")
A55: КОМПО Технолоджис | B55: РФ | C55: Шкала | D55: Оборудование | E55: Оборудование — за квартал | F55: ИТОГО по МП: | G55: 6 | H55: да | I55: 190-224 | J55: 5 | M55: 0.18 | N55: % | O55: КТ | P55: I18 | Q55: =A55&"|"&C55&"|"&D55&"|"&G55 -> КОМПО Технолоджис|Шкала|Оборудование|6 | R55: =A55&"|"&C55&"|"&D55&"|"&J55 -> КОМПО Технолоджис|Шкала|Оборудование|5 | S55: =A55&"|"&C55&"|"&D55&"|"&G55&"|"&J55 -> КОМПО Технолоджис|Шкала|Оборудование|6|5 | T55: =A55&"|"&C55&"|"&G55 -> КОМПО Технолоджис|Шкала|6 | U55: =IF(H55="да",A55&"|"&C55&"|"&D55&"|"&J55,"") -> КОМПО Технолоджис|Шкала|Оборудование|5 | V55: =IF(C55="План",A55&"|"&J55,"")
A56: КОМПО Технолоджис | B56: РФ | C56: Шкала | D56: Оборудование | E56: Оборудование — за квартал | F56: ИТОГО по МП: | G56: 6 | H56: да | I56: 225 и более | J56: 6 | M56: 0.19 | N56: % | O56: КТ | P56: J18 | Q56: =A56&"|"&C56&"|"&D56&"|"&G56 -> КОМПО Технолоджис|Шкала|Оборудование|6 | R56: =A56&"|"&C56&"|"&D56&"|"&J56 -> КОМПО Технолоджис|Шкала|Оборудование|6 | S56: =A56&"|"&C56&"|"&D56&"|"&G56&"|"&J56 -> КОМПО Технолоджис|Шкала|Оборудование|6|6 | T56: =A56&"|"&C56&"|"&G56 -> КОМПО Технолоджис|Шкала|6 | U56: =IF(H56="да",A56&"|"&C56&"|"&D56&"|"&J56,"") -> КОМПО Технолоджис|Шкала|Оборудование|6 | V56: =IF(C56="План",A56&"|"&J56,"")
A57: КОМПО Технолоджис | B57: РФ | C57: Шкала | D57: Оборудование | E57: Оборудование — за квартал | F57: Наличие минимальных складских остатков по РМ (синхронизация отчета по остаткам с 1С КОМПО) | G57: 7 | I57: до 75 | J57: 1 | M57: 0.01 | N57: % | O57: КТ | P57: E20 | Q57: =A57&"|"&C57&"|"&D57&"|"&G57 -> КОМПО Технолоджис|Шкала|Оборудование|7 | R57: =A57&"|"&C57&"|"&D57&"|"&J57 -> КОМПО Технолоджис|Шкала|Оборудование|1 | S57: =A57&"|"&C57&"|"&D57&"|"&G57&"|"&J57 -> КОМПО Технолоджис|Шкала|Оборудование|7|1 | T57: =A57&"|"&C57&"|"&G57 -> КОМПО Технолоджис|Шкала|7 | U57: =IF(H57="да",A57&"|"&C57&"|"&D57&"|"&J57,"") | V57: =IF(C57="План",A57&"|"&J57,"")
A58: КОМПО Технолоджис | B58: РФ | C58: Шкала | D58: Оборудование | E58: Оборудование — за квартал | F58: Наличие минимальных складских остатков по РМ (синхронизация отчета по остаткам с 1С КОМПО) | G58: 7 | I58: 75-114 | J58: 2 | M58: 0.01 | N58: % | O58: КТ | P58: F20 | Q58: =A58&"|"&C58&"|"&D58&"|"&G58 -> КОМПО Технолоджис|Шкала|Оборудование|7 | R58: =A58&"|"&C58&"|"&D58&"|"&J58 -> КОМПО Технолоджис|Шкала|Оборудование|2 | S58: =A58&"|"&C58&"|"&D58&"|"&G58&"|"&J58 -> КОМПО Технолоджис|Шкала|Оборудование|7|2 | T58: =A58&"|"&C58&"|"&G58 -> КОМПО Технолоджис|Шкала|7 | U58: =IF(H58="да",A58&"|"&C58&"|"&D58&"|"&J58,"") | V58: =IF(C58="План",A58&"|"&J58,"")
A59: КОМПО Технолоджис | B59: РФ | C59: Шкала | D59: Оборудование | E59: Оборудование — за квартал | F59: Наличие минимальных складских остатков по РМ (синхронизация отчета по остаткам с 1С КОМПО) | G59: 7 | I59: 115-149 | J59: 3 | M59: 0.01 | N59: % | O59: КТ | P59: G20 | Q59: =A59&"|"&C59&"|"&D59&"|"&G59 -> КОМПО Технолоджис|Шкала|Оборудование|7 | R59: =A59&"|"&C59&"|"&D59&"|"&J59 -> КОМПО Технолоджис|Шкала|Оборудование|3 | S59: =A59&"|"&C59&"|"&D59&"|"&G59&"|"&J59 -> КОМПО Технолоджис|Шкала|Оборудование|7|3 | T59: =A59&"|"&C59&"|"&G59 -> КОМПО Технолоджис|Шкала|7 | U59: =IF(H59="да",A59&"|"&C59&"|"&D59&"|"&J59,"") | V59: =IF(C59="План",A59&"|"&J59,"")
A60: КОМПО Технолоджис | B60: РФ | C60: Шкала | D60: Оборудование | E60: Оборудование — за квартал | F60: Наличие минимальных складских остатков по РМ (синхронизация отчета по остаткам с 1С КОМПО) | G60: 7 | I60: 150-189 | J60: 4 | M60: 0.01 | N60: % | O60: КТ | P60: H20 | Q60: =A60&"|"&C60&"|"&D60&"|"&G60 -> КОМПО Технолоджис|Шкала|Оборудование|7 | R60: =A60&"|"&C60&"|"&D60&"|"&J60 -> КОМПО Технолоджис|Шкала|Оборудование|4 | S60: =A60&"|"&C60&"|"&D60&"|"&G60&"|"&J60 -> КОМПО Технолоджис|Шкала|Оборудование|7|4 | T60: =A60&"|"&C60&"|"&G60 -> КОМПО Технолоджис|Шкала|7 | U60: =IF(H60="да",A60&"|"&C60&"|"&D60&"|"&J60,"") | V60: =IF(C60="План",A60&"|"&J60,"")
A61: КОМПО Технолоджис | B61: РФ | C61: Шкала | D61: Оборудование | E61: Оборудование — за квартал | F61: Наличие минимальных складских остатков по РМ (синхронизация отчета по остаткам с 1С КОМПО) | G61: 7 | I61: 190-224 | J61: 5 | M61: 0.01 | N61: % | O61: КТ | P61: I20 | Q61: =A61&"|"&C61&"|"&D61&"|"&G61 -> КОМПО Технолоджис|Шкала|Оборудование|7 | R61: =A61&"|"&C61&"|"&D61&"|"&J61 -> КОМПО Технолоджис|Шкала|Оборудование|5 | S61: =A61&"|"&C61&"|"&D61&"|"&G61&"|"&J61 -> КОМПО Технолоджис|Шкала|Оборудование|7|5 | T61: =A61&"|"&C61&"|"&G61 -> КОМПО Технолоджис|Шкала|7 | U61: =IF(H61="да",A61&"|"&C61&"|"&D61&"|"&J61,"") | V61: =IF(C61="План",A61&"|"&J61,"")
A62: КОМПО Технолоджис | B62: РФ | C62: Шкала | D62: Оборудование | E62: Оборудование — за квартал | F62: Наличие минимальных складских остатков по РМ (синхронизация отчета по остаткам с 1С КОМПО) | G62: 7 | I62: 225 и более | J62: 6 | M62: 0.01 | N62: % | O62: КТ | P62: J20 | Q62: =A62&"|"&C62&"|"&D62&"|"&G62 -> КОМПО Технолоджис|Шкала|Оборудование|7 | R62: =A62&"|"&C62&"|"&D62&"|"&J62 -> КОМПО Технолоджис|Шкала|Оборудование|6 | S62: =A62&"|"&C62&"|"&D62&"|"&G62&"|"&J62 -> КОМПО Технолоджис|Шкала|Оборудование|7|6 | T62: =A62&"|"&C62&"|"&G62 -> КОМПО Технолоджис|Шкала|7 | U62: =IF(H62="да",A62&"|"&C62&"|"&D62&"|"&J62,"") | V62: =IF(C62="План",A62&"|"&J62,"")
A63: КОМПО Технолоджис | B63: РФ | C63: Шкала | D63: Оборудование | E63: Оборудование — за квартал | F63: Объем закупок РМ | G63: 8 | I63: до 75 | J63: 1 | M63: 0 | N63: % | O63: КТ | P63: E21 | Q63: =A63&"|"&C63&"|"&D63&"|"&G63 -> КОМПО Технолоджис|Шкала|Оборудование|8 | R63: =A63&"|"&C63&"|"&D63&"|"&J63 -> КОМПО Технолоджис|Шкала|Оборудование|1 | S63: =A63&"|"&C63&"|"&D63&"|"&G63&"|"&J63 -> КОМПО Технолоджис|Шкала|Оборудование|8|1 | T63: =A63&"|"&C63&"|"&G63 -> КОМПО Технолоджис|Шкала|8 | U63: =IF(H63="да",A63&"|"&C63&"|"&D63&"|"&J63,"") | V63: =IF(C63="План",A63&"|"&J63,"")
...

Sheet Витрина
A1: ### ВИТРИНА • здесь всё считается формулами из листа «Шкалы». Править нужно там — витрина обновится сама. Лист справочный: калькулятор его не читает.
A2: Выберите дилера в ячейке B4 — ниже появятся его план и бонусы, шкала оборудования, расходных материалов и сервиса. В конце листа — сравнение всех дилеров по строке ИТОГО.
W3: Список дилеров — служебный: источник выпадающего списка в B4, пересобирается скриптом
A4: Дилер: | B4: КОМПО Технолоджис | E4: Тип: | F4: =IFERROR(INDEX('Шкалы'!$B:$B,MATCH($B$4,'Шкалы'!$A:$A,0)),"") -> РФ | G4: Отчётность: | H4: =IF($F$4="РФ","за квартал","за полугодие") -> за квартал | I4: Сервис (ЗЧ): | J4: =IFERROR(INDEX('Шкалы'!$E:$E,MATCH($B$4&"|"&"Шкала"&"|"&"Сервис (ЗЧ)"&"|"&1&"|"&1,'Шкалы'!$S:$S,0)),"") -> Сервис (ЗЧ) — расчёт по парку оборудования | W4: КОМПО Технолоджис
W5: НоваПак
A6: ПЛАН И БОНУСЫ | W6: КСП (КОМПО-СП)
A7: Категория | B7: =IFERROR(INDEX('Шкалы'!$F:$F,MATCH($B$4&"|"&1,'Шкалы'!$V:$V,0)),"") -> Выручка 2024 | C7: =IFERROR(INDEX('Шкалы'!$F:$F,MATCH($B$4&"|"&2,'Шкалы'!$V:$V,0)),"") -> Выручка 2025 | D7: =IFERROR(INDEX('Шкалы'!$F:$F,MATCH($B$4&"|"&3,'Шкалы'!$V:$V,0)),"") -> План 2026 | E7: =IFERROR(INDEX('Шкалы'!$F:$F,MATCH($B$4&"|"&4,'Шкалы'!$V:$V,0)),"") -> Прирост П/Ф | F7: =IFERROR(INDEX('Шкалы'!$F:$F,MATCH($B$4&"|"&5,'Шкалы'!$V:$V,0)),"") -> Размер бонуса по итогам 2026 г | G7: =IFERROR(INDEX('Шкалы'!$F:$F,MATCH($B$4&"|"&6,'Шкалы'!$V:$V,0)),"") -> Скидка в 1 кв. 2026 ф.г.* | W7: Богатовъ Торговый Дом, Челябинск
A8: =IFERROR(INDEX('Шкалы'!$D:$D,MATCH($B$4&"|"&"План"&"|"&1,'Шкалы'!$T:$T,0)),"") -> Итого по дилеру | B8: =IFERROR(INDEX('Шкалы'!$M:$M,MATCH($B$4&"|"&"План"&"|"&$A8&"|"&1&"|"&1,'Шкалы'!$S:$S,0)),"") -> 4164812 | C8: =IFERROR(INDEX('Шкалы'!$M:$M,MATCH($B$4&"|"&"План"&"|"&$A8&"|"&1&"|"&2,'Шкалы'!$S:$S,0)),"") -> 4121760 | D8: =IFERROR(INDEX('Шкалы'!$M:$M,MATCH($B$4&"|"&"План"&"|"&$A8&"|"&1&"|"&3,'Шкалы'!$S:$S,0)),"") -> 4142912 | E8: =IFERROR(INDEX('Шкалы'!$M:$M,MATCH($B$4&"|"&"План"&"|"&$A8&"|"&1&"|"&4,'Шкалы'!$S:$S,0)),"") -> 0.0051317859 | F8: =IFERROR(INDEX('Шкалы'!$M:$M,MATCH($B$4&"|"&"План"&"|"&$A8&"|"&1&"|"&5,'Шкалы'!$S:$S,0)),"") | G8: =IFERROR(INDEX('Шкалы'!$M:$M,MATCH($B$4&"|"&"План"&"|"&$A8&"|"&1&"|"&6,'Шкалы'!$S:$S,0)),"") | W8: ASIAN BUSINESS SOLUTIONS, Узбекистан
A9: =IFERROR(INDEX('Шкалы'!$D:$D,MATCH($B$4&"|"&"План"&"|"&2,'Шкалы'!$T:$T,0)),"") -> Сервис | B9: =IFERROR(INDEX('Шкалы'!$M:$M,MATCH($B$4&"|"&"План"&"|"&$A9&"|"&2&"|"&1,'Шкалы'!$S:$S,0)),"") -> 346883 | C9: =IFERROR(INDEX('Шкалы'!$M:$M,MATCH($B$4&"|"&"План"&"|"&$A9&"|"&2&"|"&2,'Шкалы'!$S:$S,0)),"") -> 448343 | D9: =IFERROR(INDEX('Шкалы'!$M:$M,MATCH($B$4&"|"&"План"&"|"&$A9&"|"&2&"|"&3,'Шкалы'!$S:$S,0)),"") -> 480438 | E9: =IFERROR(INDEX('Шкалы'!$M:$M,MATCH($B$4&"|"&"План"&"|"&$A9&"|"&2&"|"&4,'Шкалы'!$S:$S,0)),"") | F9: =IFERROR(INDEX('Шкалы'!$M:$M,MATCH($B$4&"|"&"План"&"|"&$A9&"|"&2&"|"&5,'Шкалы'!$S:$S,0)),"") -> 0.01 | G9: =IFERROR(INDEX('Шкалы'!$M:$M,MATCH($B$4&"|"&"План"&"|"&$A9&"|"&2&"|"&6,'Шкалы'!$S:$S,0)),"") -> 0.3 | W9: Deling food
A10: =IFERROR(INDEX('Шкалы'!$D:$D,MATCH($B$4&"|"&"План"&"|"&3,'Шкалы'!$T:$T,0)),"") -> Оборудование | B10: =IFERROR(INDEX('Шкалы'!$M:$M,MATCH($B$4&"|"&"План"&"|"&$A10&"|"&3&"|"&1,'Шкалы'!$S:$S,0)),"") -> 2205660 | C10: =IFERROR(INDEX('Шкалы'!$M:$M,MATCH($B$4&"|"&"План"&"|"&$A10&"|"&3&"|"&2,'Шкалы'!$S:$S,0)),"") -> 1710368 | D10: =IFERROR(INDEX('Шкалы'!$M:$M,MATCH($B$4&"|"&"План"&"|"&$A10&"|"&3&"|"&3,'Шкалы'!$S:$S,0)),"") -> 2020593.8 | E10: =IFERROR(INDEX('Шкалы'!$M:$M,MATCH($B$4&"|"&"План"&"|"&$A10&"|"&3&"|"&4,'Шкалы'!$S:$S,0)),"") | F10: =IFERROR(INDEX('Шкалы'!$M:$M,MATCH($B$4&"|"&"План"&"|"&$A10&"|"&3&"|"&5,'Шкалы'!$S:$S,0)),"") -> 0.015 | G10: =IFERROR(INDEX('Шкалы'!$M:$M,MATCH($B$4&"|"&"План"&"|"&$A10&"|"&3&"|"&6,'Шкалы'!$S:$S,0)),"") -> 0.19 | W10: VitLine, Казахстан
A11: =IFERROR(INDEX('Шкалы'!$D:$D,MATCH($B$4&"|"&"План"&"|"&4,'Шкалы'!$T:$T,0)),"") -> Расходные материалы | B11: =IFERROR(INDEX('Шкалы'!$M:$M,MATCH($B$4&"|"&"План"&"|"&$A11&"|"&4&"|"&1,'Шкалы'!$S:$S,0)),"") -> 1612269 | C11: =IFERROR(INDEX('Шкалы'!$M:$M,MATCH($B$4&"|"&"План"&"|"&$A11&"|"&4&"|"&2,'Шкалы'!$S:$S,0)),"") -> 1963049 | D11: =IFERROR(INDEX('Шкалы'!$M:$M,MATCH($B$4&"|"&"План"&"|"&$A11&"|"&4&"|"&3,'Шкалы'!$S:$S,0)),"") -> 1641880.2 | E11: =IFERROR(INDEX('Шкалы'!$M:$M,MATCH($B$4&"|"&"План"&"|"&$A11&"|"&4&"|"&4,'Шкалы'!$S:$S,0)),"") | F11: =IFERROR(INDEX('Шкалы'!$M:$M,MATCH($B$4&"|"&"План"&"|"&$A11&"|"&4&"|"&5,'Шкалы'!$S:$S,0)),"") -> 0.005 | G11: =IFERROR(INDEX('Шкалы'!$M:$M,MATCH($B$4&"|"&"План"&"|"&$A11&"|"&4&"|"&6,'Шкалы'!$S:$S,0)),"") -> 0.06 | W11: UNIVERSAL MEAT
A12: =IFERROR(INDEX('Шкалы'!$D:$D,MATCH($B$4&"|"&"План"&"|"&5,'Шкалы'!$T:$T,0)),"") | B12: =IFERROR(INDEX('Шкалы'!$M:$M,MATCH($B$4&"|"&"План"&"|"&$A12&"|"&5&"|"&1,'Шкалы'!$S:$S,0)),"") | C12: =IFERROR(INDEX('Шкалы'!$M:$M,MATCH($B$4&"|"&"План"&"|"&$A12&"|"&5&"|"&2,'Шкалы'!$S:$S,0)),"") | D12: =IFERROR(INDEX('Шкалы'!$M:$M,MATCH($B$4&"|"&"План"&"|"&$A12&"|"&5&"|"&3,'Шкалы'!$S:$S,0)),"") | E12: =IFERROR(INDEX('Шкалы'!$M:$M,MATCH($B$4&"|"&"План"&"|"&$A12&"|"&5&"|"&4,'Шкалы'!$S:$S,0)),"") | F12: =IFERROR(INDEX('Шкалы'!$M:$M,MATCH($B$4&"|"&"План"&"|"&$A12&"|"&5&"|"&5,'Шкалы'!$S:$S,0)),"") | G12: =IFERROR(INDEX('Шкалы'!$M:$M,MATCH($B$4&"|"&"План"&"|"&$A12&"|"&5&"|"&6,'Шкалы'!$S:$S,0)),"") | W12: КОМПО North America Inc
W13: LUCKY & S CO, Сербия
A14: ОБОРУДОВАНИЕ — шкала скидок | W14: Сейитлиев Мердан Иламанович, Туркменистан
A15: Показатель | B15: =IFERROR(INDEX('Шкалы'!$I:$I,MATCH($B$4&"|"&"Шкала"&"|"&"Оборудование"&"|"&1,'Шкалы'!$R:$R,0)),"") -> до 75 | C15: =IFERROR(INDEX('Шкалы'!$I:$I,MATCH($B$4&"|"&"Шкала"&"|"&"Оборудование"&"|"&2,'Шкалы'!$R:$R,0)),"") -> 75-114 | D15: =IFERROR(INDEX('Шкалы'!$I:$I,MATCH($B$4&"|"&"Шкала"&"|"&"Оборудование"&"|"&3,'Шкалы'!$R:$R,0)),"") -> 115-149 | E15: =IFERROR(INDEX('Шкалы'!$I:$I,MATCH($B$4&"|"&"Шкала"&"|"&"Оборудование"&"|"&4,'Шкалы'!$R:$R,0)),"") -> 150-189 | F15: =IFERROR(INDEX('Шкалы'!$I:$I,MATCH($B$4&"|"&"Шкала"&"|"&"Оборудование"&"|"&5,'Шкалы'!$R:$R,0)),"") -> 190-224 | G15: =IFERROR(INDEX('Шкалы'!$I:$I,MATCH($B$4&"|"&"Шкала"&"|"&"Оборудование"&"|"&6,'Шкалы'!$R:$R,0)),"") -> 225 и более | W15: Ingreda, Молдова
A16: =IFERROR(INDEX('Шкалы'!$F:$F,MATCH($B$4&"|"&"Шкала"&"|"&"Оборудование"&"|"&1,'Шкалы'!$Q:$Q,0)),"") -> 1 Базовое вознаграждение за Дилерский договор | B16: =IFERROR(INDEX('Шкалы'!$M:$M,MATCH($B$4&"|"&"Шкала"&"|"&"Оборудование"&"|"&1&"|"&1,'Шкалы'!$S:$S,0)),"") -> 0.06 | C16: =IFERROR(INDEX('Шкалы'!$M:$M,MATCH($B$4&"|"&"Шкала"&"|"&"Оборудование"&"|"&1&"|"&2,'Шкалы'!$S:$S,0)),"") -> 0.06 | D16: =IFERROR(INDEX('Шкалы'!$M:$M,MATCH($B$4&"|"&"Шкала"&"|"&"Оборудование"&"|"&1&"|"&3,'Шкалы'!$S:$S,0)),"") -> 0.06 | E16: =IFERROR(INDEX('Шкалы'!$M:$M,MATCH($B$4&"|"&"Шкала"&"|"&"Оборудование"&"|"&1&"|"&4,'Шкалы'!$S:$S,0)),"") -> 0.06 | F16: =IFERROR(INDEX('Шкалы'!$M:$M,MATCH($B$4&"|"&"Шкала"&"|"&"Оборудование"&"|"&1&"|"&5,'Шкалы'!$S:$S,0)),"") -> 0.06 | G16: =IFERROR(INDEX('Шкалы'!$M:$M,MATCH($B$4&"|"&"Шкала"&"|"&"Оборудование"&"|"&1&"|"&6,'Шкалы'!$S:$S,0)),"") -> 0.06 | W16: CLIPSOMAC, Алжир
A17: =IFERROR(INDEX('Шкалы'!$F:$F,MATCH($B$4&"|"&"Шкала"&"|"&"Оборудование"&"|"&2,'Шкалы'!$Q:$Q,0)),"") -> 2.1.1. Сервисный центр | B17: =IFERROR(INDEX('Шкалы'!$M:$M,MATCH($B$4&"|"&"Шкала"&"|"&"Оборудование"&"|"&2&"|"&1,'Шкалы'!$S:$S,0)),"") -> 0.06 | C17: =IFERROR(INDEX('Шкалы'!$M:$M,MATCH($B$4&"|"&"Шкала"&"|"&"Оборудование"&"|"&2&"|"&2,'Шкалы'!$S:$S,0)),"") -> 0.06 | D17: =IFERROR(INDEX('Шкалы'!$M:$M,MATCH($B$4&"|"&"Шкала"&"|"&"Оборудование"&"|"&2&"|"&3,'Шкалы'!$S:$S,0)),"") -> 0.06 | E17: =IFERROR(INDEX('Шкалы'!$M:$M,MATCH($B$4&"|"&"Шкала"&"|"&"Оборудование"&"|"&2&"|"&4,'Шкалы'!$S:$S,0)),"") -> 0.06 | F17: =IFERROR(INDEX('Шкалы'!$M:$M,MATCH($B$4&"|"&"Шкала"&"|"&"Оборудование"&"|"&2&"|"&5,'Шкалы'!$S:$S,0)),"") -> 0.06 | G17: =IFERROR(INDEX('Шкалы'!$M:$M,MATCH($B$4&"|"&"Шкала"&"|"&"Оборудование"&"|"&2&"|"&6,'Шкалы'!$S:$S,0)),"") -> 0.06 | W17: Tida Tech, Таиланд
A18: =IFERROR(INDEX('Шкалы'!$F:$F,MATCH($B$4&"|"&"Шкала"&"|"&"Оборудование"&"|"&3,'Шкалы'!$Q:$Q,0)),"") -> 2.1.2. Сервисный центр - гарантийное обслуживание | B18: =IFERROR(INDEX('Шкалы'!$M:$M,MATCH($B$4&"|"&"Шкала"&"|"&"Оборудование"&"|"&3&"|"&1,'Шкалы'!$S:$S,0)),"") -> 0.01 | C18: =IFERROR(INDEX('Шкалы'!$M:$M,MATCH($B$4&"|"&"Шкала"&"|"&"Оборудование"&"|"&3&"|"&2,'Шкалы'!$S:$S,0)),"") -> 0.01 | D18: =IFERROR(INDEX('Шкалы'!$M:$M,MATCH($B$4&"|"&"Шкала"&"|"&"Оборудование"&"|"&3&"|"&3,'Шкалы'!$S:$S,0)),"") -> 0.01 | E18: =IFERROR(INDEX('Шкалы'!$M:$M,MATCH($B$4&"|"&"Шкала"&"|"&"Оборудование"&"|"&3&"|"&4,'Шкалы'!$S:$S,0)),"") -> 0.01 | F18: =IFERROR(INDEX('Шкалы'!$M:$M,MATCH($B$4&"|"&"Шкала"&"|"&"Оборудование"&"|"&3&"|"&5,'Шкалы'!$S:$S,0)),"") -> 0.01 | G18: =IFERROR(INDEX('Шкалы'!$M:$M,MATCH($B$4&"|"&"Шкала"&"|"&"Оборудование"&"|"&3&"|"&6,'Шкалы'!$S:$S,0)),"") -> 0.01 | W18: Ari Makina, Турция
A19: =IFERROR(INDEX('Шкалы'!$F:$F,MATCH($B$4&"|"&"Шкала"&"|"&"Оборудование"&"|"&4,'Шкалы'!$Q:$Q,0)),"") -> 2.3 Наличие минимальных складских остатков по оборудованию | B19: =IFERROR(INDEX('Шкалы'!$M:$M,MATCH($B$4&"|"&"Шкала"&"|"&"Оборудование"&"|"&4&"|"&1,'Шкалы'!$S:$S,0)),"") -> 0.01 | C19: =IFERROR(INDEX('Шкалы'!$M:$M,MATCH($B$4&"|"&"Шкала"&"|"&"Оборудование"&"|"&4&"|"&2,'Шкалы'!$S:$S,0)),"") -> 0.01 | D19: =IFERROR(INDEX('Шкалы'!$M:$M,MATCH($B$4&"|"&"Шкала"&"|"&"Оборудование"&"|"&4&"|"&3,'Шкалы'!$S:$S,0)),"") -> 0.01 | E19: =IFERROR(INDEX('Шкалы'!$M:$M,MATCH($B$4&"|"&"Шкала"&"|"&"Оборудование"&"|"&4&"|"&4,'Шкалы'!$S:$S,0)),"") -> 0.01 | F19: =IFERROR(INDEX('Шкалы'!$M:$M,MATCH($B$4&"|"&"Шкала"&"|"&"Оборудование"&"|"&4&"|"&5,'Шкалы'!$S:$S,0)),"") -> 0.01 | G19: =IFERROR(INDEX('Шкалы'!$M:$M,MATCH($B$4&"|"&"Шкала"&"|"&"Оборудование"&"|"&4&"|"&6,'Шкалы'!$S:$S,0)),"") -> 0.01 | W19: Кабири Хучанд ООО, Таджикистан
A20: =IFERROR(INDEX('Шкалы'!$F:$F,MATCH($B$4&"|"&"Шкала"&"|"&"Оборудование"&"|"&5,'Шкалы'!$Q:$Q,0)),"") -> 3 Объем закупок МП | B20: =IFERROR(INDEX('Шкалы'!$M:$M,MATCH($B$4&"|"&"Шкала"&"|"&"Оборудование"&"|"&5&"|"&1,'Шкалы'!$S:$S,0)),"") -> 0 | C20: =IFERROR(INDEX('Шкалы'!$M:$M,MATCH($B$4&"|"&"Шкала"&"|"&"Оборудование"&"|"&5&"|"&2,'Шкалы'!$S:$S,0)),"") -> 0.01 | D20: =IFERROR(INDEX('Шкалы'!$M:$M,MATCH($B$4&"|"&"Шкала"&"|"&"Оборудование"&"|"&5&"|"&3,'Шкалы'!$S:$S,0)),"") -> 0.02 | E20: =IFERROR(INDEX('Шкалы'!$M:$M,MATCH($B$4&"|"&"Шкала"&"|"&"Оборудование"&"|"&5&"|"&4,'Шкалы'!$S:$S,0)),"") -> 0.03 | F20: =IFERROR(INDEX('Шкалы'!$M:$M,MATCH($B$4&"|"&"Шкала"&"|"&"Оборудование"&"|"&5&"|"&5,'Шкалы'!$S:$S,0)),"") -> 0.04 | G20: =IFERROR(INDEX('Шкалы'!$M:$M,MATCH($B$4&"|"&"Шкала"&"|"&"Оборудование"&"|"&5&"|"&6,'Шкалы'!$S:$S,0)),"") -> 0.05 | W20: Flexo Food , Грузия
A21: =IFERROR(INDEX('Шкалы'!$F:$F,MATCH($B$4&"|"&"Шкала"&"|"&"Оборудование"&"|"&6,'Шкалы'!$Q:$Q,0)),"") -> ИТОГО по МП: | B21: =IFERROR(INDEX('Шкалы'!$M:$M,MATCH($B$4&"|"&"Шкала"&"|"&"Оборудование"&"|"&6&"|"&1,'Шкалы'!$S:$S,0)),"") -> 0.14 | C21: =IFERROR(INDEX('Шкалы'!$M:$M,MATCH($B$4&"|"&"Шкала"&"|"&"Оборудование"&"|"&6&"|"&2,'Шкалы'!$S:$S,0)),"") -> 0.15 | D21: =IFERROR(INDEX('Шкалы'!$M:$M,MATCH($B$4&"|"&"Шкала"&"|"&"Оборудование"&"|"&6&"|"&3,'Шкалы'!$S:$S,0)),"") -> 0.16 | E21: =IFERROR(INDEX('Шкалы'!$M:$M,MATCH($B$4&"|"&"Шкала"&"|"&"Оборудование"&"|"&6&"|"&4,'Шкалы'!$S:$S,0)),"") -> 0.17 | F21: =IFERROR(INDEX('Шкалы'!$M:$M,MATCH($B$4&"|"&"Шкала"&"|"&"Оборудование"&"|"&6&"|"&5,'Шкалы'!$S:$S,0)),"") -> 0.18 | G21: =IFERROR(INDEX('Шкалы'!$M:$M,MATCH($B$4&"|"&"Шкала"&"|"&"Оборудование"&"|"&6&"|"&6,'Шкалы'!$S:$S,0)),"") -> 0.19 | W21: Гинап, Армения
A22: =IFERROR(INDEX('Шкалы'!$F:$F,MATCH($B$4&"|"&"Шкала"&"|"&"Оборудование"&"|"&7,'Шкалы'!$Q:$Q,0)),"") -> Наличие минимальных складских остатков по РМ (синхронизация отчета по остаткам с 1С КОМПО) | B22: =IFERROR(INDEX('Шкалы'!$M:$M,MATCH($B$4&"|"&"Шкала"&"|"&"Оборудование"&"|"&7&"|"&1,'Шкалы'!$S:$S,0)),"") -> 0.01 | C22: =IFERROR(INDEX('Шкалы'!$M:$M,MATCH($B$4&"|"&"Шкала"&"|"&"Оборудование"&"|"&7&"|"&2,'Шкалы'!$S:$S,0)),"") -> 0.01 | D22: =IFERROR(INDEX('Шкалы'!$M:$M,MATCH($B$4&"|"&"Шкала"&"|"&"Оборудование"&"|"&7&"|"&3,'Шкалы'!$S:$S,0)),"") -> 0.01 | E22: =IFERROR(INDEX('Шкалы'!$M:$M,MATCH($B$4&"|"&"Шкала"&"|"&"Оборудование"&"|"&7&"|"&4,'Шкалы'!$S:$S,0)),"") -> 0.01 | F22: =IFERROR(INDEX('Шкалы'!$M:$M,MATCH($B$4&"|"&"Шкала"&"|"&"Оборудование"&"|"&7&"|"&5,'Шкалы'!$S:$S,0)),"") -> 0.01 | G22: =IFERROR(INDEX('Шкалы'!$M:$M,MATCH($B$4&"|"&"Шкала"&"|"&"Оборудование"&"|"&7&"|"&6,'Шкалы'!$S:$S,0)),"") -> 0.01
A23: =IFERROR(INDEX('Шкалы'!$F:$F,MATCH($B$4&"|"&"Шкала"&"|"&"Оборудование"&"|"&8,'Шкалы'!$Q:$Q,0)),"") -> Объем закупок РМ | B23: =IFERROR(INDEX('Шкалы'!$M:$M,MATCH($B$4&"|"&"Шкала"&"|"&"Оборудование"&"|"&8&"|"&1,'Шкалы'!$S:$S,0)),"") -> 0 | C23: =IFERROR(INDEX('Шкалы'!$M:$M,MATCH($B$4&"|"&"Шкала"&"|"&"Оборудование"&"|"&8&"|"&2,'Шкалы'!$S:$S,0)),"") -> 0.01 | D23: =IFERROR(INDEX('Шкалы'!$M:$M,MATCH($B$4&"|"&"Шкала"&"|"&"Оборудование"&"|"&8&"|"&3,'Шкалы'!$S:$S,0)),"") -> 0.02 | E23: =IFERROR(INDEX('Шкалы'!$M:$M,MATCH($B$4&"|"&"Шкала"&"|"&"Оборудование"&"|"&8&"|"&4,'Шкалы'!$S:$S,0)),"") -> 0.03 | F23: =IFERROR(INDEX('Шкалы'!$M:$M,MATCH($B$4&"|"&"Шкала"&"|"&"Оборудование"&"|"&8&"|"&5,'Шкалы'!$S:$S,0)),"") -> 0.04 | G23: =IFERROR(INDEX('Шкалы'!$M:$M,MATCH($B$4&"|"&"Шкала"&"|"&"Оборудование"&"|"&8&"|"&6,'Шкалы'!$S:$S,0)),"") -> 0.05
A24: =IFERROR(INDEX('Шкалы'!$F:$F,MATCH($B$4&"|"&"Шкала"&"|"&"Оборудование"&"|"&9,'Шкалы'!$Q:$Q,0)),"") | B24: =IFERROR(INDEX('Шкалы'!$M:$M,MATCH($B$4&"|"&"Шкала"&"|"&"Оборудование"&"|"&9&"|"&1,'Шкалы'!$S:$S,0)),"") | C24: =IFERROR(INDEX('Шкалы'!$M:$M,MATCH($B$4&"|"&"Шкала"&"|"&"Оборудование"&"|"&9&"|"&2,'Шкалы'!$S:$S,0)),"") | D24: =IFERROR(INDEX('Шкалы'!$M:$M,MATCH($B$4&"|"&"Шкала"&"|"&"Оборудование"&"|"&9&"|"&3,'Шкалы'!$S:$S,0)),"") | E24: =IFERROR(INDEX('Шкалы'!$M:$M,MATCH($B$4&"|"&"Шкала"&"|"&"Оборудование"&"|"&9&"|"&4,'Шкалы'!$S:$S,0)),"") | F24: =IFERROR(INDEX('Шкалы'!$M:$M,MATCH($B$4&"|"&"Шкала"&"|"&"Оборудование"&"|"&9&"|"&5,'Шкалы'!$S:$S,0)),"") | G24: =IFERROR(INDEX('Шкалы'!$M:$M,MATCH($B$4&"|"&"Шкала"&"|"&"Оборудование"&"|"&9&"|"&6,'Шкалы'!$S:$S,0)),"")
A26: РАСХОДНЫЕ МАТЕРИАЛЫ — шкала скидок
A27: Показатель | B27: =IFERROR(INDEX('Шкалы'!$I:$I,MATCH($B$4&"|"&"Шкала"&"|"&"Расходные материалы"&"|"&1,'Шкалы'!$R:$R,0)),"") -> до 75 | C27: =IFERROR(INDEX('Шкалы'!$I:$I,MATCH($B$4&"|"&"Шкала"&"|"&"Расходные материалы"&"|"&2,'Шкалы'!$R:$R,0)),"") -> 75-115 | D27: =IFERROR(INDEX('Шкалы'!$I:$I,MATCH($B$4&"|"&"Шкала"&"|"&"Расходные материалы"&"|"&3,'Шкалы'!$R:$R,0)),"") -> 115-150 | E27: =IFERROR(INDEX('Шкалы'!$I:$I,MATCH($B$4&"|"&"Шкала"&"|"&"Расходные материалы"&"|"&4,'Шкалы'!$R:$R,0)),"") -> 150-190 | F27: =IFERROR(INDEX('Шкалы'!$I:$I,MATCH($B$4&"|"&"Шкала"&"|"&"Расходные материалы"&"|"&5,'Шкалы'!$R:$R,0)),"") -> 190-225 | G27: =IFERROR(INDEX('Шкалы'!$I:$I,MATCH($B$4&"|"&"Шкала"&"|"&"Расходные материалы"&"|"&6,'Шкалы'!$R:$R,0)),"") -> 225 и более
A28: =IFERROR(INDEX('Шкалы'!$F:$F,MATCH($B$4&"|"&"Шкала"&"|"&"Расходные материалы"&"|"&1,'Шкалы'!$Q:$Q,0)),"") -> Наличие минимальных складских остатков по РМ (синхронизация отчета по остаткам с 1С КОМПО) | B28: =IFERROR(INDEX('Шкалы'!$M:$M,MATCH($B$4&"|"&"Шкала"&"|"&"Расходные материалы"&"|"&1&"|"&1,'Шкалы'!$S:$S,0)),"") -> 0.01 | C28: =IFERROR(INDEX('Шкалы'!$M:$M,MATCH($B$4&"|"&"Шкала"&"|"&"Расходные материалы"&"|"&1&"|"&2,'Шкалы'!$S:$S,0)),"") -> 0.01 | D28: =IFERROR(INDEX('Шкалы'!$M:$M,MATCH($B$4&"|"&"Шкала"&"|"&"Расходные материалы"&"|"&1&"|"&3,'Шкалы'!$S:$S,0)),"") -> 0.01 | E28: =IFERROR(INDEX('Шкалы'!$M:$M,MATCH($B$4&"|"&"Шкала"&"|"&"Расходные материалы"&"|"&1&"|"&4,'Шкалы'!$S:$S,0)),"") -> 0.01 | F28: =IFERROR(INDEX('Шкалы'!$M:$M,MATCH($B$4&"|"&"Шкала"&"|"&"Расходные материалы"&"|"&1&"|"&5,'Шкалы'!$S:$S,0)),"") -> 0.01 | G28: =IFERROR(INDEX('Шкалы'!$M:$M,MATCH($B$4&"|"&"Шкала"&"|"&"Расходные материалы"&"|"&1&"|"&6,'Шкалы'!$S:$S,0)),"") -> 0.01
A29: =IFERROR(INDEX('Шкалы'!$F:$F,MATCH($B$4&"|"&"Шкала"&"|"&"Расходные материалы"&"|"&2,'Шкалы'!$Q:$Q,0)),"") -> Объем закупок РМ | B29: =IFERROR(INDEX('Шкалы'!$M:$M,MATCH($B$4&"|"&"Шкала"&"|"&"Расходные материалы"&"|"&2&"|"&1,'Шкалы'!$S:$S,0)),"") -> 0 | C29: =IFERROR(INDEX('Шкалы'!$M:$M,MATCH($B$4&"|"&"Шкала"&"|"&"Расходные материалы"&"|"&2&"|"&2,'Шкалы'!$S:$S,0)),"") -> 0.01 | D29: =IFERROR(INDEX('Шкалы'!$M:$M,MATCH($B$4&"|"&"Шкала"&"|"&"Расходные материалы"&"|"&2&"|"&3,'Шкалы'!$S:$S,0)),"") -> 0.02 | E29: =IFERROR(INDEX('Шкалы'!$M:$M,MATCH($B$4&"|"&"Шкала"&"|"&"Расходные материалы"&"|"&2&"|"&4,'Шкалы'!$S:$S,0)),"") -> 0.03 | F29: =IFERROR(INDEX('Шкалы'!$M:$M,MATCH($B$4&"|"&"Шкала"&"|"&"Расходные материалы"&"|"&2&"|"&5,'Шкалы'!$S:$S,0)),"") -> 0.04 | G29: =IFERROR(INDEX('Шкалы'!$M:$M,MATCH($B$4&"|"&"Шкала"&"|"&"Расходные материалы"&"|"&2&"|"&6,'Шкалы'!$S:$S,0)),"") -> 0.05
A30: =IFERROR(INDEX('Шкалы'!$F:$F,MATCH($B$4&"|"&"Шкала"&"|"&"Расходные материалы"&"|"&3,'Шкалы'!$Q:$Q,0)),"") | B30: =IFERROR(INDEX('Шкалы'!$M:$M,MATCH($B$4&"|"&"Шкала"&"|"&"Расходные материалы"&"|"&3&"|"&1,'Шкалы'!$S:$S,0)),"") | C30: =IFERROR(INDEX('Шкалы'!$M:$M,MATCH($B$4&"|"&"Шкала"&"|"&"Расходные материалы"&"|"&3&"|"&2,'Шкалы'!$S:$S,0)),"") | D30: =IFERROR(INDEX('Шкалы'!$M:$M,MATCH($B$4&"|"&"Шкала"&"|"&"Расходные материалы"&"|"&3&"|"&3,'Шкалы'!$S:$S,0)),"") | E30: =IFERROR(INDEX('Шкалы'!$M:$M,MATCH($B$4&"|"&"Шкала"&"|"&"Расходные материалы"&"|"&3&"|"&4,'Шкалы'!$S:$S,0)),"") | F30: =IFERROR(INDEX('Шкалы'!$M:$M,MATCH($B$4&"|"&"Шкала"&"|"&"Расходные материалы"&"|"&3&"|"&5,'Шкалы'!$S:$S,0)),"") | G30: =IFERROR(INDEX('Шкалы'!$M:$M,MATCH($B$4&"|"&"Шкала"&"|"&"Расходные материалы"&"|"&3&"|"&6,'Шкалы'!$S:$S,0)),"")
A31: =IFERROR(INDEX('Шкалы'!$F:$F,MATCH($B$4&"|"&"Шкала"&"|"&"Расходные материалы"&"|"&4,'Шкалы'!$Q:$Q,0)),"") | B31: =IFERROR(INDEX('Шкалы'!$M:$M,MATCH($B$4&"|"&"Шкала"&"|"&"Расходные материалы"&"|"&4&"|"&1,'Шкалы'!$S:$S,0)),"") | C31: =IFERROR(INDEX('Шкалы'!$M:$M,MATCH($B$4&"|"&"Шкала"&"|"&"Расходные материалы"&"|"&4&"|"&2,'Шкалы'!$S:$S,0)),"") | D31: =IFERROR(INDEX('Шкалы'!$M:$M,MATCH($B$4&"|"&"Шкала"&"|"&"Расходные материалы"&"|"&4&"|"&3,'Шкалы'!$S:$S,0)),"") | E31: =IFERROR(INDEX('Шкалы'!$M:$M,MATCH($B$4&"|"&"Шкала"&"|"&"Расходные материалы"&"|"&4&"|"&4,'Шкалы'!$S:$S,0)),"") | F31: =IFERROR(INDEX('Шкалы'!$M:$M,MATCH($B$4&"|"&"Шкала"&"|"&"Расходные материалы"&"|"&4&"|"&5,'Шкалы'!$S:$S,0)),"") | G31: =IFERROR(INDEX('Шкалы'!$M:$M,MATCH($B$4&"|"&"Шкала"&"|"&"Расходные материалы"&"|"&4&"|"&6,'Шкалы'!$S:$S,0)),"")
A33: СЕРВИС (ЗЧ) — шкала скидок
A34: Показатель | B34: =IFERROR(INDEX('Шкалы'!$I:$I,MATCH($B$4&"|"&"Шкала"&"|"&"Сервис (ЗЧ)"&"|"&1,'Шкалы'!$R:$R,0)),"") -> 0–500 | C34: =IFERROR(INDEX('Шкалы'!$I:$I,MATCH($B$4&"|"&"Шкала"&"|"&"Сервис (ЗЧ)"&"|"&2,'Шкалы'!$R:$R,0)),"") -> 501–1000 | D34: =IFERROR(INDEX('Шкалы'!$I:$I,MATCH($B$4&"|"&"Шкала"&"|"&"Сервис (ЗЧ)"&"|"&3,'Шкалы'!$R:$R,0)),"") -> 1001–1800 | E34: =IFERROR(INDEX('Шкалы'!$I:$I,MATCH($B$4&"|"&"Шкала"&"|"&"Сервис (ЗЧ)"&"|"&4,'Шкалы'!$R:$R,0)),"") -> 1801–2400 | F34: =IFERROR(INDEX('Шкалы'!$I:$I,MATCH($B$4&"|"&"Шкала"&"|"&"Сервис (ЗЧ)"&"|"&5,'Шкалы'!$R:$R,0)),"") -> 2401–3000 | G34: =IFERROR(INDEX('Шкалы'!$I:$I,MATCH($B$4&"|"&"Шкала"&"|"&"Сервис (ЗЧ)"&"|"&6,'Шкалы'!$R:$R,0)),"") -> 3001+ | H34: =IFERROR(INDEX('Шкалы'!$I:$I,MATCH($B$4&"|"&"Шкала"&"|"&"Сервис (ЗЧ)"&"|"&7,'Шкалы'!$R:$R,0)),"") | I34: =IFERROR(INDEX('Шкалы'!$I:$I,MATCH($B$4&"|"&"Шкала"&"|"&"Сервис (ЗЧ)"&"|"&8,'Шкалы'!$R:$R,0)),"") | J34: =IFERROR(INDEX('Шкалы'!$I:$I,MATCH($B$4&"|"&"Шкала"&"|"&"Сервис (ЗЧ)"&"|"&9,'Шкалы'!$R:$R,0)),"") | K34: =IFERROR(INDEX('Шкалы'!$I:$I,MATCH($B$4&"|"&"Шкала"&"|"&"Сервис (ЗЧ)"&"|"&10,'Шкалы'!$R:$R,0)),"") | L34: =IFERROR(INDEX('Шкалы'!$I:$I,MATCH($B$4&"|"&"Шкала"&"|"&"Сервис (ЗЧ)"&"|"&11,'Шкалы'!$R:$R,0)),"") | M34: =IFERROR(INDEX('Шкалы'!$I:$I,MATCH($B$4&"|"&"Шкала"&"|"&"Сервис (ЗЧ)"&"|"&12,'Шкалы'!$R:$R,0)),"")
A35: =IFERROR(INDEX('Шкалы'!$F:$F,MATCH($B$4&"|"&"Шкала"&"|"&"Сервис (ЗЧ)"&"|"&1,'Шкалы'!$Q:$Q,0)),"") -> Скидка по сервису | B35: =IFERROR(INDEX('Шкалы'!$M:$M,MATCH($B$4&"|"&"Шкала"&"|"&"Сервис (ЗЧ)"&"|"&1&"|"&1,'Шкалы'!$S:$S,0)),"") -> 0.19 | C35: =IFERROR(INDEX('Шкалы'!$M:$M,MATCH($B$4&"|"&"Шкала"&"|"&"Сервис (ЗЧ)"&"|"&1&"|"&2,'Шкалы'!$S:$S,0)),"") -> 0.21 | D35: =IFERROR(INDEX('Шкалы'!$M:$M,MATCH($B$4&"|"&"Шкала"&"|"&"Сервис (ЗЧ)"&"|"&1&"|"&3,'Шкалы'!$S:$S,0)),"") -> 0.23 | E35: =IFERROR(INDEX('Шкалы'!$M:$M,MATCH($B$4&"|"&"Шкала"&"|"&"Сервис (ЗЧ)"&"|"&1&"|"&4,'Шкалы'!$S:$S,0)),"") -> 0.25 | F35: =IFERROR(INDEX('Шкалы'!$M:$M,MATCH($B$4&"|"&"Шкала"&"|"&"Сервис (ЗЧ)"&"|"&1&"|"&5,'Шкалы'!$S:$S,0)),"") -> 0.27 | G35: =IFERROR(INDEX('Шкалы'!$M:$M,MATCH($B$4&"|"&"Шкала"&"|"&"Сервис (ЗЧ)"&"|"&1&"|"&6,'Шкалы'!$S:$S,0)),"") -> 0.3 | H35: =IFERROR(INDEX('Шкалы'!$M:$M,MATCH($B$4&"|"&"Шкала"&"|"&"Сервис (ЗЧ)"&"|"&1&"|"&7,'Шкалы'!$S:$S,0)),"") | I35: =IFERROR(INDEX('Шкалы'!$M:$M,MATCH($B$4&"|"&"Шкала"&"|"&"Сервис (ЗЧ)"&"|"&1&"|"&8,'Шкалы'!$S:$S,0)),"") | J35: =IFERROR(INDEX('Шкалы'!$M:$M,MATCH($B$4&"|"&"Шкала"&"|"&"Сервис (ЗЧ)"&"|"&1&"|"&9,'Шкалы'!$S:$S,0)),"") | K35: =IFERROR(INDEX('Шкалы'!$M:$M,MATCH($B$4&"|"&"Шкала"&"|"&"Сервис (ЗЧ)"&"|"&1&"|"&10,'Шкалы'!$S:$S,0)),"") | L35: =IFERROR(INDEX('Шкалы'!$M:$M,MATCH($B$4&"|"&"Шкала"&"|"&"Сервис (ЗЧ)"&"|"&1&"|"&11,'Шкалы'!$S:$S,0)),"") | M35: =IFERROR(INDEX('Шкалы'!$M:$M,MATCH($B$4&"|"&"Шкала"&"|"&"Сервис (ЗЧ)"&"|"&1&"|"&12,'Шкалы'!$S:$S,0)),"")
A37: СРАВНЕНИЕ ДИЛЕРОВ — строка ИТОГО по оборудованию
A38: Дилер | B38: =B15 -> до 75 | C38: =C15 -> 75-114 | D38: =D15 -> 115-149 | E38: =E15 -> 150-189 | F38: =F15 -> 190-224 | G38: =G15 -> 225 и более | H38: Тип
A39: =$W$4 -> КОМПО Технолоджис | B39: =IFERROR(INDEX('Шкалы'!$M:$M,MATCH($A39&"|"&"Шкала"&"|"&"Оборудование"&"|"&1,'Шкалы'!$U:$U,0)),"") -> 0.14 | C39: =IFERROR(INDEX('Шкалы'!$M:$M,MATCH($A39&"|"&"Шкала"&"|"&"Оборудование"&"|"&2,'Шкалы'!$U:$U,0)),"") -> 0.15 | D39: =IFERROR(INDEX('Шкалы'!$M:$M,MATCH($A39&"|"&"Шкала"&"|"&"Оборудование"&"|"&3,'Шкалы'!$U:$U,0)),"") -> 0.16 | E39: =IFERROR(INDEX('Шкалы'!$M:$M,MATCH($A39&"|"&"Шкала"&"|"&"Оборудование"&"|"&4,'Шкалы'!$U:$U,0)),"") -> 0.17 | F39: =IFERROR(INDEX('Шкалы'!$M:$M,MATCH($A39&"|"&"Шкала"&"|"&"Оборудование"&"|"&5,'Шкалы'!$U:$U,0)),"") -> 0.18 | G39: =IFERROR(INDEX('Шкалы'!$M:$M,MATCH($A39&"|"&"Шкала"&"|"&"Оборудование"&"|"&6,'Шкалы'!$U:$U,0)),"") -> 0.19 | H39: =IFERROR(INDEX('Шкалы'!$B:$B,MATCH($A39,'Шкалы'!$A:$A,0)),"") -> РФ
A40: =$W$5 -> НоваПак | B40: =IFERROR(INDEX('Шкалы'!$M:$M,MATCH($A40&"|"&"Шкала"&"|"&"Оборудование"&"|"&1,'Шкалы'!$U:$U,0)),"") -> 0.14 | C40: =IFERROR(INDEX('Шкалы'!$M:$M,MATCH($A40&"|"&"Шкала"&"|"&"Оборудование"&"|"&2,'Шкалы'!$U:$U,0)),"") -> 0.15 | D40: =IFERROR(INDEX('Шкалы'!$M:$M,MATCH($A40&"|"&"Шкала"&"|"&"Оборудование"&"|"&3,'Шкалы'!$U:$U,0)),"") -> 0.16 | E40: =IFERROR(INDEX('Шкалы'!$M:$M,MATCH($A40&"|"&"Шкала"&"|"&"Оборудование"&"|"&4,'Шкалы'!$U:$U,0)),"") -> 0.17 | F40: =IFERROR(INDEX('Шкалы'!$M:$M,MATCH($A40&"|"&"Шкала"&"|"&"Оборудование"&"|"&5,'Шкалы'!$U:$U,0)),"") -> 0.18 | G40: =IFERROR(INDEX('Шкалы'!$M:$M,MATCH($A40&"|"&"Шкала"&"|"&"Оборудование"&"|"&6,'Шкалы'!$U:$U,0)),"") -> 0.19 | H40: =IFERROR(INDEX('Шкалы'!$B:$B,MATCH($A40,'Шкалы'!$A:$A,0)),"") -> РФ
A41: =$W$6 -> КСП (КОМПО-СП) | B41: =IFERROR(INDEX('Шкалы'!$M:$M,MATCH($A41&"|"&"Шкала"&"|"&"Оборудование"&"|"&1,'Шкалы'!$U:$U,0)),"") -> 0.14 | C41: =IFERROR(INDEX('Шкалы'!$M:$M,MATCH($A41&"|"&"Шкала"&"|"&"Оборудование"&"|"&2,'Шкалы'!$U:$U,0)),"") -> 0.15 | D41: =IFERROR(INDEX('Шкалы'!$M:$M,MATCH($A41&"|"&"Шкала"&"|"&"Оборудование"&"|"&3,'Шкалы'!$U:$U,0)),"") -> 0.16 | E41: =IFERROR(INDEX('Шкалы'!$M:$M,MATCH($A41&"|"&"Шкала"&"|"&"Оборудование"&"|"&4,'Шкалы'!$U:$U,0)),"") -> 0.17 | F41: =IFERROR(INDEX('Шкалы'!$M:$M,MATCH($A41&"|"&"Шкала"&"|"&"Оборудование"&"|"&5,'Шкалы'!$U:$U,0)),"") -> 0.18 | G41: =IFERROR(INDEX('Шкалы'!$M:$M,MATCH($A41&"|"&"Шкала"&"|"&"Оборудование"&"|"&6,'Шкалы'!$U:$U,0)),"") -> 0.19 | H41: =IFERROR(INDEX('Шкалы'!$B:$B,MATCH($A41,'Шкалы'!$A:$A,0)),"") -> РФ
A42: =$W$7 -> Богатовъ Торговый Дом, Челябинск | B42: =IFERROR(INDEX('Шкалы'!$M:$M,MATCH($A42&"|"&"Шкала"&"|"&"Оборудование"&"|"&1,'Шкалы'!$U:$U,0)),"") -> 0.14 | C42: =IFERROR(INDEX('Шкалы'!$M:$M,MATCH($A42&"|"&"Шкала"&"|"&"Оборудование"&"|"&2,'Шкалы'!$U:$U,0)),"") -> 0.15 | D42: =IFERROR(INDEX('Шкалы'!$M:$M,MATCH($A42&"|"&"Шкала"&"|"&"Оборудование"&"|"&3,'Шкалы'!$U:$U,0)),"") -> 0.16 | E42: =IFERROR(INDEX('Шкалы'!$M:$M,MATCH($A42&"|"&"Шкала"&"|"&"Оборудование"&"|"&4,'Шкалы'!$U:$U,0)),"") -> 0.17 | F42: =IFERROR(INDEX('Шкалы'!$M:$M,MATCH($A42&"|"&"Шкала"&"|"&"Оборудование"&"|"&5,'Шкалы'!$U:$U,0)),"") -> 0.18 | G42: =IFERROR(INDEX('Шкалы'!$M:$M,MATCH($A42&"|"&"Шкала"&"|"&"Оборудование"&"|"&6,'Шкалы'!$U:$U,0)),"") -> 0.19 | H42: =IFERROR(INDEX('Шкалы'!$B:$B,MATCH($A42,'Шкалы'!$A:$A,0)),"") -> РФ
A43: =$W$8 -> ASIAN BUSINESS SOLUTIONS, Узбекистан | B43: =IFERROR(INDEX('Шкалы'!$M:$M,MATCH($A43&"|"&"Шкала"&"|"&"Оборудование"&"|"&1,'Шкалы'!$U:$U,0)),"") -> 0.14 | C43: =IFERROR(INDEX('Шкалы'!$M:$M,MATCH($A43&"|"&"Шкала"&"|"&"Оборудование"&"|"&2,'Шкалы'!$U:$U,0)),"") -> 0.16 | D43: =IFERROR(INDEX('Шкалы'!$M:$M,MATCH($A43&"|"&"Шкала"&"|"&"Оборудование"&"|"&3,'Шкалы'!$U:$U,0)),"") -> 0.17 | E43: =IFERROR(INDEX('Шкалы'!$M:$M,MATCH($A43&"|"&"Шкала"&"|"&"Оборудование"&"|"&4,'Шкалы'!$U:$U,0)),"") -> 0.18 | F43: =IFERROR(INDEX('Шкалы'!$M:$M,MATCH($A43&"|"&"Шкала"&"|"&"Оборудование"&"|"&5,'Шкалы'!$U:$U,0)),"") -> 0.19 | G43: =IFERROR(INDEX('Шкалы'!$M:$M,MATCH($A43&"|"&"Шкала"&"|"&"Оборудование"&"|"&6,'Шкалы'!$U:$U,0)),"") -> 0.2 | H43: =IFERROR(INDEX('Шкалы'!$B:$B,MATCH($A43,'Шкалы'!$A:$A,0)),"") -> Заруб
...

Sheet Блоки
A1: БЛОКИ ДИЛЕРОВ — копия исходных вкладок, для сверки с оригиналом
A2: Каждый дилер — блок строк, над ним строка-маркер (ячейка A начинается с «### ДИЛЕР»). Строки блока сгруппированы: сворачиваются кнопкой слева.
A3: Править шкалы нужно на листе «Шкалы» (плоская таблица) — именно её читает калькулятор. Лист «Витрина» показывает те же данные глазами.
A4: Этот лист калькулятор разбирает только как запасной вариант — если листа «Шкалы» в файле не окажется. Формулы, форматы, объединённые ячейки и оформление перенесены из исходника 1:1.
A5: Собрано автоматически из legacy/scales_multisheet_2026.xlsx (21 вкладок → 18 блоков) • tools/consolidate_scales.py • 2026-10-02
A7: СОДЕРЖАНИЕ — клик по строке переносит к блоку дилера
A8: 1 • КОМПО Технолоджис • РФ • вкладка «КТ» • блок в строке 28
A9: 2 • НоваПак • РФ • вкладка «НоваПак» • блок в строке 70
A10: 3 • КСП (КОМПО-СП) • РФ • вкладка «КСП» • блок в строке 112
A11: 4 • Богатовъ Торговый Дом, Челябинск • РФ • вкладка «Богатовъ Торговый Дом, Челябинс» • блок в строке 155
A12: 5 • ASIAN BUSINESS SOLUTIONS, Узбекистан • Заруб • вкладка «ABS» • блок в строке 197
A13: 6 • Deling food • Заруб • вкладка «Deling fod» • блок в строке 234
... A28: ### ДИЛЕР 1/18 • КОМПО Технолоджис • РФ (отчётность за квартал) • вкладка «КТ» • исходные строки 1–39 (A1:K39)
D31: Выручка 2024 | E31: Выручка 2025 | F31: План 2026 | G31: Прирост П/Ф | H31: Размер бонуса по итогам 2026 г | I31: Скидка в 1 кв. 2026 ф.г.*
C32: КОМПО Технолоджис | D32: 4164812 | E32: 4121760 | F32: =SUM(F33:F35) -> 4142912 | G32: =F32/E32-1 -> 0.0051317859
C33: Сервис | D33: 346883 | E33: 448343 | F33: 480438 | H33: 0.01 | I33: 0.3
C34: Оборудование | D34: 2205660 | E34: 1710368 | F34: 2020593.8 | H34: 0.015 | I34: 0.19
C35: Расходные материалы | D35: 1612269 | E35: 1963049 | F35: 1641880.2 | H35: 0.005 | I35: 0.06
C36: * - скидка согласно правил работы ТПС на 2026 ф.г.
C37: Ретробонус насчитывается и выплачивается по каждому направлению отдельно при выполнении плана 100% и более. Каждое направление имеет свой % бонусирования. Бонусирование вступает в силу к расчету только при условии выполнения плана ИТОГО на 95%. При отсутствии просроченной Дебиторской Задолженности бонус выплачивается в полном размере.
C39: 3.1.1. Система предоставления скидок
C40: ОБЪЕМ закупок оборудования (тысяч евро) за 3 месяца (квартал) | E40: до 75 | F40: 75-114 | G40: 115-149 | H40: 150-189 | I40: 190-224 | J40: 225 и более
C41: 1 Базовое вознаграждение за Дилерский договор | D41: Скидка % | E41: 6 | F41: 6 | G41: 6 | H41: 6 | I41: 6 | J41: 6
C42: 2.1.1. Сервисный центр | D42: Скидка % | E42: 6 | F42: 6 | G42: 6 | H42: 6 | I42: 6 | J42: 6
C43: 2.1.2. Сервисный центр - гарантийное обслуживание | D43: Скидка % | E43: 1 | F43: 1 | G43: 1 | H43: 1 | I43: 1 | J43: 1
B44: ??? | C44: 2.3 Наличие минимальных складских остатков по оборудованию | D44: Ретро-скидка % | E44: 1 | F44: 1 | G44: 1 | H44: 1 | I44: 1 | J44: 1
C45: 3 Объем закупок МП | D45: скидка будущих периодов % | E45: 0 | F45: 1 | G45: 2 | H45: 3 | I45: 4 | J45: 5
C46: ИТОГО по МП: | E46: =SUM(E41:E45) -> 14 | F46: =SUM(F41:F45) -> 15 | G46: =SUM(G41:G45) -> 16 | H46: =SUM(H41:H45) -> 17 | I46: =SUM(I41:I45) -> 18 | J46: =SUM(J41:J45) -> 19
C47: ОБЪЕМ закупок РМ (тысяч евро) за 3 месяца (квартал) | E47: до 75 | F47: 75-115 | G47: 115-150 | H47: 150-190 | I47: 190-225 | J47: 225 и более
C48: Наличие минимальных складских остатков по РМ (синхронизация отчета по остаткам с 1С КОМПО) | D48: Скидка будущих периодов, % | E48: 1 | F48: 1 | G48: 1 | H48: 1 | I48: 1 | J48: 1
C49: Объем закупок РМ | D49: скидка будущих периодов, % | E49: 0 | F49: 1 | G49: 2 | H49: 3 | I49: 4 | J49: 5
C51: СИСТЕМА РАСЧЕТА СКИДКИ ПО ЗАПЧАСТЯМ
D52: Отношение объема закупок ЗЧ к парку оборудования, евро / ед. об. | F52: Процент скидки
D53: без статуса партнера | F53: 0.15
C54: диапазон отношения | D54: 0 | E54: 500 | F54: 0.19
C55: диапазон отношения | D55: 501 | E55: 1000 | F55: 0.21
C56: диапазон отношения | D56: 1001 | E56: 1800 | F56: 0.23
C57: диапазон отношения | D57: 1801 | E57: 2400 | F57: 0.25
C58: диапазон отношения | D58: 2401 | E58: 3000 | F58: 0.27
C59: диапазон отношения | D59: 3001 | F59: 0.3
...
